<?xml version="1.0" ?>
<!-- =================================================================================== -->
<!-- |    This document was autogenerated by xacro from /home/paulmathieu/hydro/stacks/reemc_common/reemc_description/robots/reemc_lower_body.urdf.xacro | -->
<!-- |    EDITING THIS FILE BY HAND IS NOT RECOMMENDED                                 | -->
<!-- =================================================================================== -->
<!--

  Copyright (c) 2011, PAL Robotics, S.L.
  All rights reserved.

  This work is licensed under the Creative Commons Attribution-NonCommercial-NoDerivs 3.0 Unported License.
  To view a copy of this license, visit http://creativecommons.org/licenses/by-nc-nd/3.0/ or send a letter to
  Creative Commons, 444 Castro Street, Suite 900, Mountain View, California, 94041, USA.
-->
<robot name="reemc" xmlns:controller="http://playerstage.sourceforge.net/gazebo/xmlschema/#controller" xmlns:interface="http://playerstage.sourceforge.net/gazebo/xmlschema/#interface" xmlns:sensor="http://playerstage.sourceforge.net/gazebo/xmlschema/#sensor" xmlns:xacro="http://ros.org/wiki/xacro">
  <link name="base_link">
    <inertial>
      <mass value="36.85"/>
      <origin rpy="0 0 0" xyz="0.0 0.0 0.0"/>
      <inertia ixx="0.066949617" ixy="0" ixz="0" iyy="0.072510104" iyz="0.0" izz="0.093793054"/>
    </inertial>
    <visual>
      <origin rpy="0 0 0" xyz="0 0 0.0"/>
      <geometry>
        <box size="0.2 0.295 0.278"/>
      </geometry>
      <material name="LightGrey"/>
    </visual>
    <collision>
      <origin rpy="0 0 0" xyz="0 0 0.0"/>
      <geometry>
        <box size="0.2 0.295 0.278"/>
      </geometry>
    </collision>
  </link>
  <gazebo>
    <!-- robot model offset -->
    <pose>0 0 0.85 0 0 0</pose>
  </gazebo>
  <!-- The following included files set up definitions of parts of the robot body -->
  <!-- Torso -->
  <!-- Head -->
  <!-- Arm -->
  <!-- Hand -->
  <!-- Sensors -->
  <!-- Generic simulator_gazebo plugins -->
  <gazebo>
    <plugin filename="libgazebo_ros_control.so" name="gazebo_ros_control">
      <ns/>
      <robotSimType>reemc_hardware_gazebo/ReemcHardwareGazebo</robotSimType>
      <robotNamespace/>
      <controlPeriod>0.001</controlPeriod>
    </plugin>
    <plugin filename="libgazebo_ros_p3d.so" name="gazebo_ros_p3d">
      <bodyName>base_link</bodyName>
      <topicName>ground_truth_odom</topicName>
      <alwaysOn>true</alwaysOn>
      <updateRate>100.0</updateRate>
    </plugin>
  </gazebo>
  <gazebo>
    <plugin filename="libgazebo_ros_force.so" name="gazebo_ros_force">
      <bodyName>reemc::base_link</bodyName>
      <topicName>base_link_wrench</topicName>
    </plugin>
  </gazebo>
  <gazebo reference="imu_link">
    <!-- this is expected to be reparented to pelvis with appropriate offset
         when imu_link is reduced by fixed joint reduction -->
    <!-- todo: this is working with gazebo 1.4, need to write a unit test -->
    <sensor name="imu_sensor" type="imu">
      <always_on>1</always_on>
      <update_rate>1000.0</update_rate>
      <imu>
        <noise>
          <type>gaussian</type>
          <!-- Noise parameters from Boston Dynamics
               (http://gazebosim.org/wiki/Sensor_noise):
                 rates (rad/s): mean=0, stddev=2e-4
                 accels (m/s/s): mean=0, stddev=1.7e-2
                 rate bias (rad/s): 5e-6 - 1e-5
                 accel bias (m/s/s): 1e-1
               Experimentally, simulation provide rates with noise of
               about 1e-3 rad/s and accels with noise of about 1e-1 m/s/s.
               So we don't expect to see the noise unless number of inner iterations
               are increased.

               We will add bias.  In this model, bias is sampled once for rates
               and once for accels at startup; the sign (negative or positive)
               of each bias is then switched with equal probability.  Thereafter,
               the biases are fixed additive offsets.  We choose
               bias means and stddevs to produce biases close to the provided
               data. -->
          <rate>
            <mean>0.0</mean>
            <stddev>2e-4</stddev>
            <bias_mean>0.0000075</bias_mean>
            <bias_stddev>0.0000008</bias_stddev>
          </rate>
          <accel>
            <mean>0.0</mean>
            <stddev>1.7e-2</stddev>
            <bias_mean>0.1</bias_mean>
            <bias_stddev>0.001</bias_stddev>
          </accel>
        </noise>
      </imu>
    </sensor>
  </gazebo>
  <gazebo reference="r_foot">
    <mu1>0.9</mu1>
    <mu2>0.9</mu2>
    <fdir1>1 0 0</fdir1>
    <maxVel>1.0</maxVel>
    <minDepth>0.003</minDepth>
  </gazebo>
  <gazebo reference="l_foot">
    <mu1>0.9</mu1>
    <mu2>0.9</mu2>
    <fdir1>1 0 0</fdir1>
    <maxVel>1.0</maxVel>
    <minDepth>0.003</minDepth>
  </gazebo>
  <!-- Materials for visualization -->
  <material name="Blue">
    <color rgba="0.0 0.0 0.8 1.0"/>
  </material>
  <material name="Green">
    <color rgba="0.0 0.8 0.0 1.0"/>
  </material>
  <material name="Grey">
    <color rgba="0.7 0.7 0.7 1.0"/>
  </material>
  <material name="LightGrey">
    <color rgba="0.9 0.9 0.9 1.0"/>
  </material>
  <material name="DarkGrey">
    <color rgba="0.2 0.2 0.2 1.0"/>
  </material>
  <material name="Red">
    <color rgba="0.8 0.0 0.0 1.0"/>
  </material>
  <material name="White">
    <color rgba="1.0 1.0 1.0 1.0"/>
  </material>
  <!-- Now we can start using the macros included above to define the actual robot -->
  <!-- The reflect parameter takes the value 1 or -1 to respectively distinguish right from left side in expressions -->
  <link name="leg_right_1_link">
    <inertial>
      <mass value="1.02901"/>
      <origin rpy="0 0 0" xyz="-0.02571 0 0.02557"/>
      <inertia ixx="0.00132187534" ixy="0.00000001514" ixz="0.00040022268" iyy="0.0018528617" iyz="0.00000050713" izz="0.00084231334"/>
    </inertial>
    <visual>
      <origin rpy="0 0 0" xyz="0 0 0"/>
      <geometry>
        <mesh filename="package://reemc_description/meshes/leg/leg_1.stl" scale="1 1 1"/>
      </geometry>
      <material name="LightGrey"/>
    </visual>
  </link>
  <joint name="leg_right_1_joint" type="revolute">
    <origin rpy="0 0 0" xyz="0  -0.075 -0.139"/>
    <axis xyz="0 0 1"/>
    <parent link="base_link"/>
    <child link="leg_right_1_link"/>
    <dynamics damping="1.0" friction="1.0"/>
    <limit effort="42.84" lower="-0.785398163397" upper="0.523598775598" velocity="2.35"/>
    <safety_controller k_position="100" k_velocity="100" soft_lower_limit="-0.785398163397" soft_upper_limit="0.523598775598"/>
  </joint>
  <link name="leg_right_2_link">
    <inertial>
      <mass value="0.69621"/>
      <origin rpy="0.0 0.0 0.0" xyz="0.00057 -0.00881 -0.01125"/>
      <inertia ixx="0.0008416476" ixy="-0.00000268743" ixz="0.00000667199" iyy="0.00039794844" iyz="0.00002668971" izz="0.00084196694"/>
    </inertial>
    <visual>
      <origin rpy="1.57079632679 0 0" xyz="0 0 0"/>
      <geometry>
        <cylinder length="0.10" radius="0.04"/>
      </geometry>
      <material name="LightGrey"/>
    </visual>
  </link>
  <joint name="leg_right_2_joint" type="revolute">
    <origin rpy="0 1.57079632679 0" xyz="0 0 0.0"/>
    <axis xyz="0 0 1"/>
    <parent link="leg_right_1_link"/>
    <child link="leg_right_2_link"/>
    <dynamics damping="1.0" friction="1.0"/>
    <limit effort="69.1" lower="-0.523598775598" upper="0.261799387799" velocity="2.27"/>
    <safety_controller k_position="100" k_velocity="100" soft_lower_limit="-0.523598775598" soft_upper_limit="0.261799387799"/>
  </joint>
  <link name="leg_right_3_link">
    <inertial>
      <mass value="3.97852"/>
      <origin rpy="0.0 0 0.0" xyz="0.14784 -0.01646 -0.01793"/>
      <inertia ixx="0.00507885174" ixy="-0.00034076421" ixz="-0.00225952731" iyy="0.02850097402" iyz="0.00003047874" izz="0.02632392239"/>
    </inertial>
    <visual>
      <origin rpy="3.14159265359 0 0" xyz="0 0 0"/>
      <geometry>
        <mesh filename="package://reemc_description/meshes/leg/leg_3.stl" scale="1 1 -1.0"/>
      </geometry>
      <material name="LightGrey"/>
    </visual>
    <collision group="default">
      <origin rpy="0 1.57079632679 0" xyz="0.15 0 -0.015"/>
      <geometry>
        <box size="0.15 0.10 0.20"/>
      </geometry>
    </collision>
  </link>
  <joint name="leg_right_3_joint" type="revolute">
    <origin rpy="-1.57079632679 0 0" xyz="0 0 0.0"/>
    <axis xyz="0 0 1"/>
    <parent link="leg_right_2_link"/>
    <child link="leg_right_3_link"/>
    <dynamics damping="1.0" friction="1.0"/>
    <limit effort="55.26" lower="-1.74532925199" upper="0.785398163397" velocity="3.64"/>
    <safety_controller k_position="100" k_velocity="100" soft_lower_limit="-1.74532925199" soft_upper_limit="0.785398163397"/>
  </joint>
  <link name="leg_right_4_link">
    <inertial>
      <mass value="2.86055"/>
      <origin rpy="0.0 0.0 0.0" xyz="0.14618 -0.0022 -0.02189"/>
      <inertia ixx="0.00361006492" ixy="0.00012218208" ixz="0.00160208242" iyy="0.02470649045" iyz="0.00008129755" izz="0.02272322206"/>
    </inertial>
    <visual>
      <origin rpy="0 0 0" xyz="0 0 0"/>
      <geometry>
        <mesh filename="package://reemc_description/meshes/leg/leg_4.stl" scale="1 1 -1.0"/>
      </geometry>
      <material name="LightGrey"/>
    </visual>
    <collision group="default">
      <origin rpy="0 -1.57079632679 0" xyz="0.15 0 -0.015"/>
      <geometry>
        <box size="0.15 0.10 0.20"/>
      </geometry>
    </collision>
  </link>
  <joint name="leg_right_4_joint" type="revolute">
    <origin rpy="0 0 0" xyz="0.300 0 0.0"/>
    <axis xyz="0 0 1"/>
    <parent link="leg_right_3_link"/>
    <child link="leg_right_4_link"/>
    <dynamics damping="0.1" friction="0"/>
    <dynamics damping="1.0" friction="1.0"/>
    <limit effort="138.28" lower="0.0" upper="2.61799387799" velocity="3.25"/>
    <safety_controller k_position="100" k_velocity="100" soft_lower_limit="0.0" soft_upper_limit="2.61799387799"/>
  </joint>
  <link name="leg_right_5_link">
    <inertial>
      <mass value="0.68213"/>
      <origin rpy="0.0 0.0 0.0" xyz="-0.00028 0.01119 -0.00859"/>
      <inertia ixx="0.00082035023" ixy="0.00000048534" ixz="0.00000226301" iyy="0.00082074105" iyz="-0.00002892247" izz="0.00037614067"/>
    </inertial>
    <visual>
      <origin rpy="0 0 0" xyz="0 0 0"/>
      <geometry>
        <cylinder length="0.104" radius="0.04"/>
      </geometry>
      <material name="LightGrey"/>
    </visual>
  </link>
  <joint name="leg_right_5_joint" type="revolute">
    <origin rpy="0 0 0" xyz="0.30 0 0.0"/>
    <axis xyz="0 0 1"/>
    <parent link="leg_right_4_link"/>
    <child link="leg_right_5_link"/>
    <dynamics damping="1.0" friction="1.0"/>
    <limit effort="68.51" lower="-1.74532925199" upper="0.785398163397" velocity="2.44"/>
    <safety_controller k_position="100" k_velocity="100" soft_lower_limit="-1.74532925199" soft_upper_limit="0.785398163397"/>
  </joint>
  <link name="leg_right_6_link">
    <inertial>
      <mass value="2.00843"/>
      <origin rpy="0.0 0.0 0.0" xyz="0.06111 -0.00336 -0.00497"/>
      <inertia ixx="0.00366502559" ixy="0.00020479295" ixz="0.00112439297" iyy="0.00532618026" iyz="0.00012133755" izz="0.00353091463"/>
    </inertial>
    <visual>
      <origin rpy="0 -1.57079632679 0" xyz="0.110 0 0"/>
      <geometry>
        <mesh filename="package://reemc_description/meshes/leg/sole.stl" scale="1 -1.0 1"/>
      </geometry>
      <material name="LightGrey"/>
    </visual>
    <collision>
      <origin rpy="0 0 0" xyz="0.1 -0.01 0.025 "/>
      <geometry>
        <box size="0.02 0.14 0.210"/>
      </geometry>
    </collision>
  </link>
  <joint name="leg_right_6_joint" type="revolute">
    <origin rpy="1.57079632679 0 0" xyz="0 0 0"/>
    <axis xyz="0 0 1"/>
    <parent link="leg_right_5_link"/>
    <child link="leg_right_6_link"/>
    <dynamics damping="1.0" friction="1.0"/>
    <limit effort="80.9" lower="-0.261799387799" upper="0.523598775598" velocity="2.27"/>
    <safety_controller k_position="100" k_velocity="100" soft_lower_limit="-0.261799387799" soft_upper_limit="0.523598775598"/>
  </joint>
  <link name="right_sole_link">
    <inertial>
      <mass value="0.001"/>
      <origin rpy="0 0 0" xyz="0 0 0"/>
      <inertia ixx="0.0" ixy="0.0" ixz="0.0" iyy="0.0" iyz="0.0" izz="0.0"/>
    </inertial>
  </link>
  <joint name="right_sole_joint" type="fixed">
    <!-- origin x taken from link_${side}_6_link/visual/origin/x above -->
    <origin rpy="0.0 -1.57079632679 0.0" xyz="0.110 0.0 0.0"/>
    <axis xyz="0 0 1"/>
    <parent link="leg_right_6_link"/>
    <child link="right_sole_link"/>
    <dynamics damping="1.0" friction="1.0"/>
    <limit effort="60" lower="0.0" upper="0.0" velocity="0"/>
  </joint>
  <gazebo reference="leg_right_1_link">
    <mu1>0.9</mu1>
    <mu2>0.9</mu2>
  </gazebo>
  <gazebo reference="leg_right_2_link">
    <mu1>0.9</mu1>
    <mu2>0.9</mu2>
  </gazebo>
  <gazebo reference="leg_right_3_link">
    <mu1>0.9</mu1>
    <mu2>0.9</mu2>
  </gazebo>
  <gazebo reference="leg_right_4_link">
    <mu1>0.9</mu1>
    <mu2>0.9</mu2>
  </gazebo>
  <gazebo reference="leg_right_5_link">
    <mu1>0.9</mu1>
    <mu2>0.9</mu2>
  </gazebo>
  <gazebo reference="leg_right_6_link">
    <kp>1000000.0</kp>
    <kd>100.0</kd>
    <mu1>1.0</mu1>
    <mu2>1.0</mu2>
    <fdir1>0 0 1</fdir1>
    <maxVel>1.0</maxVel>
    <minDepth>0.00</minDepth>
    <implicitSpringDamper>1</implicitSpringDamper>
  </gazebo>
  <gazebo reference="leg_right_1_joint">
    <implicitSpringDamper>1</implicitSpringDamper>
  </gazebo>
  <gazebo reference="leg_right_2_joint">
    <implicitSpringDamper>1</implicitSpringDamper>
  </gazebo>
  <gazebo reference="leg_right_3_joint">
    <implicitSpringDamper>1</implicitSpringDamper>
  </gazebo>
  <gazebo reference="leg_right_4_joint">
    <implicitSpringDamper>1</implicitSpringDamper>
  </gazebo>
  <gazebo reference="leg_right_5_joint">
    <implicitSpringDamper>1</implicitSpringDamper>
  </gazebo>
  <gazebo reference="leg_right_6_joint">
    <implicitSpringDamper>1</implicitSpringDamper>
    <provideFeedback>1</provideFeedback>
  </gazebo>
  <transmission name="leg_right_1_trans">
    <type>transmission_interface/SimpleTransmission</type>
    <actuator name="leg_right_1_motor">
      <mechanicalReduction>1.0</mechanicalReduction>
      <hardwareInterface>hardware_interface/PositionJointInterface</hardwareInterface>
    </actuator>
    <joint name="leg_right_1_joint"/>
  </transmission>
  <transmission name="leg_right_2_trans">
    <type>transmission_interface/SimpleTransmission</type>
    <actuator name="leg_right_2_motor">
      <mechanicalReduction>1.0</mechanicalReduction>
      <hardwareInterface>hardware_interface/PositionJointInterface</hardwareInterface>
    </actuator>
    <joint name="leg_right_2_joint"/>
  </transmission>
  <transmission name="leg_right_3_trans">
    <type>transmission_interface/SimpleTransmission</type>
    <actuator name="leg_right_3_motor">
      <mechanicalReduction>1.0</mechanicalReduction>
      <hardwareInterface>hardware_interface/PositionJointInterface</hardwareInterface>
    </actuator>
    <joint name="leg_right_3_joint"/>
  </transmission>
  <transmission name="leg_right_4_trans">
    <type>transmission_interface/SimpleTransmission</type>
    <actuator name="leg_right_4_motor">
      <mechanicalReduction>1.0</mechanicalReduction>
      <hardwareInterface>hardware_interface/PositionJointInterface</hardwareInterface>
    </actuator>
    <joint name="leg_right_4_joint"/>
  </transmission>
  <transmission name="leg_right_5_trans">
    <type>transmission_interface/SimpleTransmission</type>
    <actuator name="leg_right_5_motor">
      <mechanicalReduction>1.0</mechanicalReduction>
      <hardwareInterface>hardware_interface/PositionJointInterface</hardwareInterface>
    </actuator>
    <joint name="leg_right_5_joint"/>
  </transmission>
  <transmission name="leg_right_6_trans">
    <type>transmission_interface/SimpleTransmission</type>
    <actuator name="leg_right_6_motor">
      <mechanicalReduction>1.0</mechanicalReduction>
      <hardwareInterface>hardware_interface/PositionJointInterface</hardwareInterface>
    </actuator>
    <joint name="leg_right_6_joint"/>
  </transmission>
  <link name="right_laser_link">
    <inertial>
      <origin rpy="0 0 0" xyz="0.0 0.0 0.0"/>
      <mass value="0.001"/>
      <inertia ixx="3.7174E-05" ixy="4.9927E-08" ixz="1.1015E-05" iyy="4.2412E-05" iyz="-9.8165E-09" izz="4.167E-05"/>
    </inertial>
    <!--    <visual>
         <origin xyz="0.0 0 0.05" rpy="0 0 ${90.0*deg_to_rad}" />
        <geometry>
          <mesh filename="package://reemc_description/meshes/sensors/urg-04lx-ug01.stl" scale="0.001 0.001 0.001"/>
        </geometry>
      <material name="DarkGrey" />
      </visual>
  -->
  </link>
  <joint name="right_laser_joint" type="fixed">
    <axis xyz="0 1 0"/>
    <origin rpy="0.0 0.0 -0.523598775598" xyz="0.085 -0.01 0.04"/>
    <parent link="right_sole_link"/>
    <child link="right_laser_link"/>
    <dynamics damping="1" friction="1.0"/>
    <limit effort="60" lower="0" upper="0" velocity="20"/>
  </joint>
  <gazebo reference="right_laser_link">
    <sensor name="right_laser_sensor" type="ray">
      <pose>0 0 0 0 0 0</pose>
      <visualize>false</visualize>
      <update_rate>10.0</update_rate>
      <ray>
        <scan>
          <horizontal>
            <samples>360</samples>
            <resolution>1</resolution>
            <min_angle>-1.57079632679</min_angle>
            <max_angle>1.57079632679</max_angle>
          </horizontal>
        </scan>
        <range>
          <min>0.02</min>
          <max>4.0</max>
          <resolution>0.01</resolution>
        </range>
      </ray>
      <plugin filename="libgazebo_ros_laser.so" name="gazebo_ros_laser">
        <frameName>/right_laser_link</frameName>
        <topicName>right_scan</topicName>
        <gaussianNoise>0.0</gaussianNoise>
        <hokuyoMinIntensity>101</hokuyoMinIntensity>
        <updateRate>10.0</updateRate>
        <alwaysOn>true</alwaysOn>
      </plugin>
    </sensor>
  </gazebo>
  <link name="leg_left_1_link">
    <inertial>
      <mass value="1.02901"/>
      <origin rpy="0 0 0" xyz="-0.02571 0 0.02557"/>
      <inertia ixx="0.00132187534" ixy="0.00000001514" ixz="0.00040022268" iyy="0.0018528617" iyz="0.00000050713" izz="0.00084231334"/>
    </inertial>
    <visual>
      <origin rpy="0 0 0" xyz="0 0 0"/>
      <geometry>
        <mesh filename="package://reemc_description/meshes/leg/leg_1.stl" scale="1 1 1"/>
      </geometry>
      <material name="LightGrey"/>
    </visual>
  </link>
  <joint name="leg_left_1_joint" type="revolute">
    <origin rpy="0 0 0" xyz="0  0.075 -0.139"/>
    <axis xyz="0 0 1"/>
    <parent link="base_link"/>
    <child link="leg_left_1_link"/>
    <dynamics damping="1.0" friction="1.0"/>
    <limit effort="42.84" lower="-0.785398163397" upper="0.523598775598" velocity="2.35"/>
    <safety_controller k_position="100" k_velocity="100" soft_lower_limit="-0.785398163397" soft_upper_limit="0.523598775598"/>
  </joint>
  <link name="leg_left_2_link">
    <inertial>
      <mass value="0.69621"/>
      <origin rpy="0.0 0.0 0.0" xyz="0.00057 0.00881 -0.01125"/>
      <inertia ixx="0.0008416476" ixy="-0.00000268743" ixz="0.00000667199" iyy="0.00039794844" iyz="0.00002668971" izz="0.00084196694"/>
    </inertial>
    <visual>
      <origin rpy="1.57079632679 0 0" xyz="0 0 0"/>
      <geometry>
        <cylinder length="0.10" radius="0.04"/>
      </geometry>
      <material name="LightGrey"/>
    </visual>
  </link>
  <joint name="leg_left_2_joint" type="revolute">
    <origin rpy="0 1.57079632679 0" xyz="0 0 0.0"/>
    <axis xyz="0 0 1"/>
    <parent link="leg_left_1_link"/>
    <child link="leg_left_2_link"/>
    <dynamics damping="1.0" friction="1.0"/>
    <limit effort="69.1" lower="-0.261799387799" upper="0.523598775598" velocity="2.27"/>
    <safety_controller k_position="100" k_velocity="100" soft_lower_limit="-0.261799387799" soft_upper_limit="0.523598775598"/>
  </joint>
  <link name="leg_left_3_link">
    <inertial>
      <mass value="3.97852"/>
      <origin rpy="0.0 0 0.0" xyz="0.14784 -0.01646 0.01793"/>
      <inertia ixx="0.00507885174" ixy="-0.00034076421" ixz="-0.00225952731" iyy="0.02850097402" iyz="0.00003047874" izz="0.02632392239"/>
    </inertial>
    <visual>
      <origin rpy="3.14159265359 0 0" xyz="0 0 0"/>
      <geometry>
        <mesh filename="package://reemc_description/meshes/leg/leg_3.stl" scale="1 1 1.0"/>
      </geometry>
      <material name="LightGrey"/>
    </visual>
    <collision group="default">
      <origin rpy="0 1.57079632679 0" xyz="0.15 0 0.015"/>
      <geometry>
        <box size="0.15 0.10 0.20"/>
      </geometry>
    </collision>
  </link>
  <joint name="leg_left_3_joint" type="revolute">
    <origin rpy="-1.57079632679 0 0" xyz="0 0 0.0"/>
    <axis xyz="0 0 1"/>
    <parent link="leg_left_2_link"/>
    <child link="leg_left_3_link"/>
    <dynamics damping="1.0" friction="1.0"/>
    <limit effort="55.26" lower="-1.74532925199" upper="0.785398163397" velocity="3.64"/>
    <safety_controller k_position="100" k_velocity="100" soft_lower_limit="-1.74532925199" soft_upper_limit="0.785398163397"/>
  </joint>
  <link name="leg_left_4_link">
    <inertial>
      <mass value="2.86055"/>
      <origin rpy="0.0 0.0 0.0" xyz="0.14618 -0.0022 0.02189"/>
      <inertia ixx="0.00361006492" ixy="0.00012218208" ixz="0.00160208242" iyy="0.02470649045" iyz="0.00008129755" izz="0.02272322206"/>
    </inertial>
    <visual>
      <origin rpy="0 0 0" xyz="0 0 0"/>
      <geometry>
        <mesh filename="package://reemc_description/meshes/leg/leg_4.stl" scale="1 1 1.0"/>
      </geometry>
      <material name="LightGrey"/>
    </visual>
    <collision group="default">
      <origin rpy="0 1.57079632679 0" xyz="0.15 0 0.015"/>
      <geometry>
        <box size="0.15 0.10 0.20"/>
      </geometry>
    </collision>
  </link>
  <joint name="leg_left_4_joint" type="revolute">
    <origin rpy="0 0 0" xyz="0.300 0 0.0"/>
    <axis xyz="0 0 1"/>
    <parent link="leg_left_3_link"/>
    <child link="leg_left_4_link"/>
    <dynamics damping="0.1" friction="0"/>
    <dynamics damping="1.0" friction="1.0"/>
    <limit effort="138.28" lower="0.0" upper="2.61799387799" velocity="3.25"/>
    <safety_controller k_position="100" k_velocity="100" soft_lower_limit="0.0" soft_upper_limit="2.61799387799"/>
  </joint>
  <link name="leg_left_5_link">
    <inertial>
      <mass value="0.68213"/>
      <origin rpy="0.0 0.0 0.0" xyz="-0.00028 0.01119 0.00859"/>
      <inertia ixx="0.00082035023" ixy="0.00000048534" ixz="0.00000226301" iyy="0.00082074105" iyz="-0.00002892247" izz="0.00037614067"/>
    </inertial>
    <visual>
      <origin rpy="0 0 0" xyz="0 0 0"/>
      <geometry>
        <cylinder length="0.104" radius="0.04"/>
      </geometry>
      <material name="LightGrey"/>
    </visual>
  </link>
  <joint name="leg_left_5_joint" type="revolute">
    <origin rpy="0 0 0" xyz="0.30 0 0.0"/>
    <axis xyz="0 0 1"/>
    <parent link="leg_left_4_link"/>
    <child link="leg_left_5_link"/>
    <dynamics damping="1.0" friction="1.0"/>
    <limit effort="68.51" lower="-1.74532925199" upper="0.785398163397" velocity="2.44"/>
    <safety_controller k_position="100" k_velocity="100" soft_lower_limit="-1.74532925199" soft_upper_limit="0.785398163397"/>
  </joint>
  <link name="leg_left_6_link">
    <inertial>
      <mass value="2.00843"/>
      <origin rpy="0.0 0.0 0.0" xyz="0.06111 0.00336 -0.00497"/>
      <inertia ixx="0.00366502559" ixy="0.00020479295" ixz="0.00112439297" iyy="0.00532618026" iyz="0.00012133755" izz="0.00353091463"/>
    </inertial>
    <visual>
      <origin rpy="0 -1.57079632679 0" xyz="0.110 0 0"/>
      <geometry>
        <mesh filename="package://reemc_description/meshes/leg/sole.stl" scale="1 1.0 1"/>
      </geometry>
      <material name="LightGrey"/>
    </visual>
    <collision>
      <origin rpy="0 0 0" xyz="0.1 0.01 0.025 "/>
      <geometry>
        <box size="0.02 0.14 0.210"/>
      </geometry>
    </collision>
  </link>
  <joint name="leg_left_6_joint" type="revolute">
    <origin rpy="1.57079632679 0 0" xyz="0 0 0"/>
    <axis xyz="0 0 1"/>
    <parent link="leg_left_5_link"/>
    <child link="leg_left_6_link"/>
    <dynamics damping="1.0" friction="1.0"/>
    <limit effort="80.9" lower="-0.261799387799" upper="0.523598775598" velocity="2.27"/>
    <safety_controller k_position="100" k_velocity="100" soft_lower_limit="-0.261799387799" soft_upper_limit="0.523598775598"/>
  </joint>
  <link name="left_sole_link">
    <inertial>
      <mass value="0.001"/>
      <origin rpy="0 0 0" xyz="0 0 0"/>
      <inertia ixx="0.0" ixy="0.0" ixz="0.0" iyy="0.0" iyz="0.0" izz="0.0"/>
    </inertial>
  </link>
  <joint name="left_sole_joint" type="fixed">
    <!-- origin x taken from link_${side}_6_link/visual/origin/x above -->
    <origin rpy="0.0 -1.57079632679 0.0" xyz="0.110 0.0 0.0"/>
    <axis xyz="0 0 1"/>
    <parent link="leg_left_6_link"/>
    <child link="left_sole_link"/>
    <dynamics damping="1.0" friction="1.0"/>
    <limit effort="60" lower="0.0" upper="0.0" velocity="0"/>
  </joint>
  <gazebo reference="leg_left_1_link">
    <mu1>0.9</mu1>
    <mu2>0.9</mu2>
  </gazebo>
  <gazebo reference="leg_left_2_link">
    <mu1>0.9</mu1>
    <mu2>0.9</mu2>
  </gazebo>
  <gazebo reference="leg_left_3_link">
    <mu1>0.9</mu1>
    <mu2>0.9</mu2>
  </gazebo>
  <gazebo reference="leg_left_4_link">
    <mu1>0.9</mu1>
    <mu2>0.9</mu2>
  </gazebo>
  <gazebo reference="leg_left_5_link">
    <mu1>0.9</mu1>
    <mu2>0.9</mu2>
  </gazebo>
  <gazebo reference="leg_left_6_link">
    <kp>1000000.0</kp>
    <kd>100.0</kd>
    <mu1>1.0</mu1>
    <mu2>1.0</mu2>
    <fdir1>0 0 1</fdir1>
    <maxVel>1.0</maxVel>
    <minDepth>0.00</minDepth>
    <implicitSpringDamper>1</implicitSpringDamper>
  </gazebo>
  <gazebo reference="leg_left_1_joint">
    <implicitSpringDamper>1</implicitSpringDamper>
  </gazebo>
  <gazebo reference="leg_left_2_joint">
    <implicitSpringDamper>1</implicitSpringDamper>
  </gazebo>
  <gazebo reference="leg_left_3_joint">
    <implicitSpringDamper>1</implicitSpringDamper>
  </gazebo>
  <gazebo reference="leg_left_4_joint">
    <implicitSpringDamper>1</implicitSpringDamper>
  </gazebo>
  <gazebo reference="leg_left_5_joint">
    <implicitSpringDamper>1</implicitSpringDamper>
  </gazebo>
  <gazebo reference="leg_left_6_joint">
    <implicitSpringDamper>1</implicitSpringDamper>
    <provideFeedback>1</provideFeedback>
  </gazebo>
  <transmission name="leg_left_1_trans">
    <type>transmission_interface/SimpleTransmission</type>
    <actuator name="leg_left_1_motor">
      <mechanicalReduction>1.0</mechanicalReduction>
      <hardwareInterface>hardware_interface/PositionJointInterface</hardwareInterface>
    </actuator>
    <joint name="leg_left_1_joint"/>
  </transmission>
  <transmission name="leg_left_2_trans">
    <type>transmission_interface/SimpleTransmission</type>
    <actuator name="leg_left_2_motor">
      <mechanicalReduction>1.0</mechanicalReduction>
      <hardwareInterface>hardware_interface/PositionJointInterface</hardwareInterface>
    </actuator>
    <joint name="leg_left_2_joint"/>
  </transmission>
  <transmission name="leg_left_3_trans">
    <type>transmission_interface/SimpleTransmission</type>
    <actuator name="leg_left_3_motor">
      <mechanicalReduction>1.0</mechanicalReduction>
      <hardwareInterface>hardware_interface/PositionJointInterface</hardwareInterface>
    </actuator>
    <joint name="leg_left_3_joint"/>
  </transmission>
  <transmission name="leg_left_4_trans">
    <type>transmission_interface/SimpleTransmission</type>
    <actuator name="leg_left_4_motor">
      <mechanicalReduction>1.0</mechanicalReduction>
      <hardwareInterface>hardware_interface/PositionJointInterface</hardwareInterface>
    </actuator>
    <joint name="leg_left_4_joint"/>
  </transmission>
  <transmission name="leg_left_5_trans">
    <type>transmission_interface/SimpleTransmission</type>
    <actuator name="leg_left_5_motor">
      <mechanicalReduction>1.0</mechanicalReduction>
      <hardwareInterface>hardware_interface/PositionJointInterface</hardwareInterface>
    </actuator>
    <joint name="leg_left_5_joint"/>
  </transmission>
  <transmission name="leg_left_6_trans">
    <type>transmission_interface/SimpleTransmission</type>
    <actuator name="leg_left_6_motor">
      <mechanicalReduction>1.0</mechanicalReduction>
      <hardwareInterface>hardware_interface/PositionJointInterface</hardwareInterface>
    </actuator>
    <joint name="leg_left_6_joint"/>
  </transmission>
  <link name="left_laser_link">
    <inertial>
      <origin rpy="0 0 0" xyz="0.0 0.0 0.0"/>
      <mass value="0.001"/>
      <inertia ixx="3.7174E-05" ixy="4.9927E-08" ixz="1.1015E-05" iyy="4.2412E-05" iyz="-9.8165E-09" izz="4.167E-05"/>
    </inertial>
    <!--    <visual>
         <origin xyz="0.0 0 0.05" rpy="0 0 ${90.0*deg_to_rad}" />
        <geometry>
          <mesh filename="package://reemc_description/meshes/sensors/urg-04lx-ug01.stl" scale="0.001 0.001 0.001"/>
        </geometry>
      <material name="DarkGrey" />
      </visual>
  -->
  </link>
  <joint name="left_laser_joint" type="fixed">
    <axis xyz="0 1 0"/>
    <origin rpy="0.0 0.0 0.523598775598" xyz="0.085 0.01 0.04"/>
    <parent link="left_sole_link"/>
    <child link="left_laser_link"/>
    <dynamics damping="1" friction="1.0"/>
    <limit effort="60" lower="0" upper="0" velocity="20"/>
  </joint>
  <gazebo reference="left_laser_link">
    <sensor name="left_laser_sensor" type="ray">
      <pose>0 0 0 0 0 0</pose>
      <visualize>false</visualize>
      <update_rate>10.0</update_rate>
      <ray>
        <scan>
          <horizontal>
            <samples>360</samples>
            <resolution>1</resolution>
            <min_angle>-1.57079632679</min_angle>
            <max_angle>1.57079632679</max_angle>
          </horizontal>
        </scan>
        <range>
          <min>0.02</min>
          <max>4.0</max>
          <resolution>0.01</resolution>
        </range>
      </ray>
      <plugin filename="libgazebo_ros_laser.so" name="gazebo_ros_laser">
        <frameName>/left_laser_link</frameName>
        <topicName>left_scan</topicName>
        <gaussianNoise>0.0</gaussianNoise>
        <hokuyoMinIntensity>101</hokuyoMinIntensity>
        <updateRate>10.0</updateRate>
        <alwaysOn>true</alwaysOn>
      </plugin>
    </sensor>
  </gazebo>
  <!-- imu -->
  <link name="imu_link">
    <inertial>
      <mass value="0.01"/>
      <origin xyz="0 0 0"/>
      <inertia ixx="0.000001" ixy="0" ixz="0" iyy="0.000001" iyz="0" izz="0.000001"/>
    </inertial>
    <visual>
      <origin rpy="0 0 0" xyz="0 0 0"/>
      <geometry>
        <box size="0.01 0.01 0.01"/>
      </geometry>
    </visual>
  </link>
  <joint name="imu_joint" type="fixed">
    <parent link="base_link"/>
    <child link="imu_link"/>
    <origin rpy="0 0 0" xyz="0.0 0 0.0"/>
  </joint>
</robot>
